<?xml version="1.0" ?>
<!--
  Ignition Gazebo Ackermann steering plugin demo

  Try sending commands:

    ign topic -t "/model/vehicle_blue/cmd_vel" -m ignition.msgs.Twist -p "linear: {x: 0.5}, angular: {z: 0.1}"

  Listen to odometry:

    ign topic -e -t /model/vehicle_blue/odometry

-->
<sdf version="1.6">
  <world name="ackermann_steering">

    <physics name="1ms" type="ignored">
      <max_step_size>0.001</max_step_size>
      <real_time_factor>1.0</real_time_factor>
    </physics>
    <plugin
      filename="ignition-gazebo-physics-system"
      name="ignition::gazebo::systems::Physics">
    </plugin>
    <plugin
      filename="ignition-gazebo-user-commands-system"
      name="ignition::gazebo::systems::UserCommands">
    </plugin>
    <plugin
      filename="ignition-gazebo-scene-broadcaster-system"
      name="ignition::gazebo::systems::SceneBroadcaster">
    </plugin>

    <light type="directional" name="sun">
      <cast_shadows>true</cast_shadows>
      <pose>0 0 10 0 0 0</pose>
      <diffuse>1 1 1 1</diffuse>
      <specular>0.5 0.5 0.5 1</specular>
      <attenuation>
        <range>1000</range>
        <constant>0.9</constant>
        <linear>0.01</linear>
        <quadratic>0.001</quadratic>
      </attenuation>
      <direction>-0.5 0.1 -0.9</direction>
    </light>

    <model name="ground_plane">
      <static>true</static>
      <link name="link">
        <collision name="collision">
          <geometry>
            <plane>
              <normal>0 0 1</normal>
              <size>100 100</size>
            </plane>
          </geometry>
          <surface>
            <friction>
              <ode>
                <mu>50</mu>
              </ode>
            </friction>
          </surface>
        </collision>
        <visual name="visual">
          <geometry>
            <plane>
              <normal>0 0 1</normal>
              <size>100 100</size>
            </plane>
          </geometry>
          <material>
            <ambient>0.8 0.8 0.8 1</ambient>
            <diffuse>0.8 0.8 0.8 1</diffuse>
            <specular>0.8 0.8 0.8 1</specular>
          </material>
        </visual>
      </link>
    </model>

    <model name='vehicle_blue'>
      <pose>0 2 0.325 0 -0 0</pose>

      <link name='chassis'>
        <pose>-0.151427 -0 0.175 0 -0 0</pose>
        <inertial>
          <mass>1.14395</mass>
          <inertia>
            <ixx>0.126164</ixx>
            <ixy>0</ixy>
            <ixz>0</ixz>
            <iyy>0.416519</iyy>
            <iyz>0</iyz>
            <izz>0.481014</izz>
          </inertia>
        </inertial>
        <visual name='visual'>
          <geometry>
            <box>
              <size>2.01142 1 0.568726</size>
            </box>
          </geometry>
          <material>
            <ambient>0.5 0.5 1.0 1</ambient>
            <diffuse>0.5 0.5 1.0 1</diffuse>
            <specular>0.0 0.0 1.0 1</specular>
          </material>
        </visual>
        <collision name='collision'>
          <geometry>
            <box>
              <size>2.01142 1 0.568726</size>
            </box>
          </geometry>
        </collision>
      </link>

      <link name='front_left_wheel'>
        <pose>0.554283 0.625029 -0.025 -1.5707 0 0</pose>
        <inertial>
          <mass>2</mass>
          <inertia>
            <ixx>0.145833</ixx>
            <ixy>0</ixy>
            <ixz>0</ixz>
            <iyy>0.145833</iyy>
            <iyz>0</iyz>
            <izz>0.125</izz>
          </inertia>
        </inertial>
        <visual name='visual'>
          <geometry>
            <cylinder>
              <length>0.15</length>
              <radius>0.3</radius>
            </cylinder>
          </geometry>
          <material>
            <ambient>0.2 0.2 0.2 1</ambient>
            <diffuse>0.2 0.2 0.2 1</diffuse>
            <specular>0.2 0.2 0.2 1</specular>
          </material>
        </visual>
        <collision name='collision'>
          <geometry>
            <cylinder>
              <length>0.15</length>
              <radius>0.3</radius>
            </cylinder>
          </geometry>
          <surface>
            <friction>
              <ode>
                <mu>0.5</mu>
                <mu2>1.0</mu2>
                <fdir1>0 0 1</fdir1>
              </ode>
            </friction>
          </surface>
        </collision>
      </link>

      <link name='rear_left_wheel'>
        <pose>-0.957138 0.625029 -0.025 -1.5707 0 0</pose>
        <inertial>
          <mass>2</mass>
          <inertia>
            <ixx>0.145833</ixx>
            <ixy>0</ixy>
            <ixz>0</ixz>
            <iyy>0.145833</iyy>
            <iyz>0</iyz>
            <izz>0.125</izz>
          </inertia>
        </inertial>
        <visual name='visual'>
          <geometry>
            <cylinder>
              <length>0.15</length>
              <radius>0.3</radius>
            </cylinder>
          </geometry>
          <material>
            <ambient>0.2 0.2 0.2 1</ambient>
            <diffuse>0.2 0.2 0.2 1</diffuse>
            <specular>0.2 0.2 0.2 1</specular>
          </material>
        </visual>
        <collision name='collision'>
          <geometry>
            <cylinder>
              <length>0.15</length>
              <radius>0.3</radius>
            </cylinder>
          </geometry>
          <surface>
            <friction>
              <ode>
                <mu>0.5</mu>
                <mu2>1.0</mu2>
                <fdir1>0 0 1</fdir1>
              </ode>
            </friction>
          </surface>
        </collision>
      </link>

      <link name='front_right_wheel'>
        <pose>0.554282 -0.625029 -0.025 -1.5707 0 0</pose>
        <inertial>
          <mass>2</mass>
          <inertia>
            <ixx>0.145833</ixx>
            <ixy>0</ixy>
            <ixz>0</ixz>
            <iyy>0.145833</iyy>
            <iyz>0</iyz>
            <izz>0.125</izz>
          </inertia>
        </inertial>
        <visual name='visual'>
          <geometry>
            <cylinder>
              <length>0.15</length>
              <radius>0.3</radius>
            </cylinder>
          </geometry>
          <material>
            <ambient>0.2 0.2 0.2 1</ambient>
            <diffuse>0.2 0.2 0.2 1</diffuse>
            <specular>0.2 0.2 0.2 1</specular>
          </material>
        </visual>
        <collision name='collision'>
          <geometry>
            <cylinder>
              <length>0.15</length>
              <radius>0.3</radius>
            </cylinder>
          </geometry>
          <surface>
            <friction>
              <ode>
                <mu>0.5</mu>
                <mu2>1.0</mu2>
                <fdir1>0 0 1</fdir1>
              </ode>
            </friction>
          </surface>
        </collision>
      </link>

      <link name='rear_right_wheel'>
        <pose>-0.957138 -0.625029 -0.025 -1.5707 0 0</pose>
        <inertial>
          <mass>2</mass>
          <inertia>
            <ixx>0.145833</ixx>
            <ixy>0</ixy>
            <ixz>0</ixz>
            <iyy>0.145833</iyy>
            <iyz>0</iyz>
            <izz>0.125</izz>
          </inertia>
        </inertial>
        <visual name='visual'>
          <geometry>
            <cylinder>
              <length>0.15</length>
              <radius>0.3</radius>
            </cylinder>
          </geometry>
          <material>
            <ambient>0.2 0.2 0.2 1</ambient>
            <diffuse>0.2 0.2 0.2 1</diffuse>
            <specular>0.2 0.2 0.2 1</specular>
          </material>
        </visual>
        <collision name='collision'>
          <geometry>
            <cylinder>
              <length>0.15</length>
              <radius>0.3</radius>
            </cylinder>
          </geometry>
          <surface>
            <friction>
              <ode>
                <mu>0.5</mu>
                <mu2>1.0</mu2>
                <fdir1>0 0 1</fdir1>
              </ode>
            </friction>
          </surface>
        </collision>
      </link>

      <link name="front_left_wheel_steering_link">
        <pose>0.554283 0.5 0.02 0 0 0</pose>
        <inertial>
          <mass>0.5</mass>
          <inertia>
            <ixx>0.0153</ixx>
            <iyy>0.025</iyy>
            <izz>0.0153</izz>
          </inertia>
        </inertial>
        <visual name="steering_link_visual">
          <pose>0 0 0 0 0 0</pose>
          <geometry>
            <cylinder>
              <length>0.1</length>
              <radius>0.03</radius>
            </cylinder>
          </geometry>
          <material>
            <ambient>1 1 1</ambient>
            <diffuse>1 1 1</diffuse>
          </material>
        </visual>
      </link>

      <link name="front_right_wheel_steering_link">
        <pose>0.554283 -0.5 0.02 0 0 0</pose>
        <inertial>
          <mass>0.5</mass>
          <inertia>
            <ixx>0.0153</ixx>
            <iyy>0.025</iyy>
            <izz>0.0153</izz>
          </inertia>
        </inertial>
        <visual name="steering_link_visual">
          <pose>0 0 0 0 0 0</pose>
          <geometry>
            <cylinder>
              <length>0.1</length>
              <radius>0.03</radius>
            </cylinder>
          </geometry>
          <material>
            <ambient>1 1 1</ambient>
            <diffuse>1 1 1</diffuse>
          </material>
        </visual>
      </link>

      <joint name="front_left_wheel_steering_joint" type="revolute">
        <child>front_left_wheel_steering_link</child>
        <parent>chassis</parent>
        <axis>
          <xyz>0 0 1</xyz>
          <limit>
            <lower>-0.6</lower>
            <upper>+0.6</upper>
            <velocity>1.0</velocity>
            <effort>25</effort>
          </limit>
          <use_parent_model_frame>1</use_parent_model_frame>
        </axis>
      </joint>

      <joint name="front_right_wheel_steering_joint" type="revolute">
        <parent>chassis</parent>
        <child>front_right_wheel_steering_link</child>
        <axis>
          <xyz>0 0 1</xyz>
          <limit>
            <lower>-0.6</lower>
            <upper>+0.6</upper>
            <velocity>1.0</velocity>
            <effort>25</effort>
          </limit>
        </axis>
      </joint>

      <joint name='front_left_wheel_joint' type='revolute'>
        <parent>front_left_wheel_steering_link</parent>
        <child>front_left_wheel</child>
        <axis>
          <xyz>0 0 1</xyz>
          <limit>
            <lower>-1.79769e+308</lower>
            <upper>1.79769e+308</upper>
          </limit>
        </axis>
      </joint>

      <joint name='front_right_wheel_joint' type='revolute'>
        <parent>front_right_wheel_steering_link</parent>
        <child>front_right_wheel</child>
        <axis>
          <xyz>0 0 1</xyz>
          <limit>
            <lower>-1.79769e+308</lower>
            <upper>1.79769e+308</upper>
          </limit>
        </axis>
      </joint>

      <joint name='rear_left_wheel_joint' type='revolute'>
        <parent>chassis</parent>
        <child>rear_left_wheel</child>
        <axis>
          <xyz>0 0 1</xyz>
          <limit>
            <lower>-1.79769e+308</lower>
            <upper>1.79769e+308</upper>
          </limit>
        </axis>
      </joint>

      <joint name='rear_right_wheel_joint' type='revolute'>
        <parent>chassis</parent>
        <child>rear_right_wheel</child>
        <axis>
          <xyz>0 0 1</xyz>
          <limit>
            <lower>-1.79769e+308</lower>
            <upper>1.79769e+308</upper>
          </limit>
        </axis>
      </joint>

      <plugin
        filename="ignition-gazebo-ackermann-steering-system"
        name="ignition::gazebo::systems::AckermannSteering">
        <left_joint>front_left_wheel_joint</left_joint>
        <left_joint>rear_left_wheel_joint</left_joint>
        <right_joint>front_right_wheel_joint</right_joint>
        <right_joint>rear_right_wheel_joint</right_joint>
        <left_steering_joint>front_left_wheel_steering_joint</left_steering_joint>
        <right_steering_joint>front_right_wheel_steering_joint</right_steering_joint>
        <kingpin_width>1.0</kingpin_width>
        <steering_limit>0.5</steering_limit>
        <wheel_base>1.0</wheel_base>
        <wheel_separation>1.25</wheel_separation>
        <wheel_radius>0.3</wheel_radius>
        <min_velocity>-1</min_velocity>
        <max_velocity>1</max_velocity>
        <min_acceleration>-3</min_acceleration>
        <max_acceleration>3</max_acceleration>
      </plugin>

    </model>

  </world>
</sdf>
