<?xml version="1.0" ?>
<!--
  Gazebo joint controller plugin demo

  Try sending joint velocity commands (velocity mode):

    gz topic -t "/model/joint_controller_demo/joint/j1/cmd_vel" -m gz.msgs.Double -p "data: -1.0"

    gz topic -t "/model/joint_controller_demo/joint/j1/cmd_vel" -m gz.msgs.Double -p "data: 10.0"

  Try sending joint velocity commands (force mode):

    gz topic -t "/model/joint_controller_demo_2/joint/j1/cmd_vel" -m gz.msgs.Double -p "data: -1.0"

    gz topic -t "/model/joint_controller_demo_2/joint/j1/cmd_vel" -m gz.msgs.Double -p "data: 10.0"
-->
<sdf version="1.6">
  <world name="default">
    <plugin
      filename="gz-sim-physics-system"
      name="gz::sim::systems::Physics">
    </plugin>
    <plugin
      filename="gz-sim-scene-broadcaster-system"
      name="gz::sim::systems::SceneBroadcaster">
    </plugin>

    <light type="directional" name="sun">
      <cast_shadows>true</cast_shadows>
      <pose>0 0 10 0 0 0</pose>
      <diffuse>1 1 1 1</diffuse>
      <specular>0.5 0.5 0.5 1</specular>
      <attenuation>
        <range>1000</range>
        <constant>0.9</constant>
        <linear>0.01</linear>
        <quadratic>0.001</quadratic>
      </attenuation>
      <direction>-0.5 0.1 -0.9</direction>
    </light>
    <model name="joint_controller_demo">
      <pose>0 0 0 0 -1.57 0</pose>
      <link name="base_link">
        <pose>0.0 0.0 0.0 0 0 0</pose>
        <inertial>
          <inertia>
            <ixx>2.501</ixx>
            <ixy>0</ixy>
            <ixz>0</ixz>
            <iyy>2.501</iyy>
            <iyz>0</iyz>
            <izz>5</izz>
          </inertia>
          <mass>120.0</mass>
        </inertial>
        <visual name="base_visual">
          <pose>0.0 0.0 0.0 0 0 0</pose>
          <geometry>
            <box>
              <size>0.5 0.5 0.01</size>
            </box>
          </geometry>
        </visual>
        <collision name="base_collision">
          <pose>0.0 0.0 0.0 0 0 0</pose>
          <geometry>
            <box>
              <size>0.5 0.5 0.01</size>
            </box>
          </geometry>
        </collision>
      </link>
      <link name="rotor">
        <pose>0.0 0.0 0.1 0 0 0</pose>
        <inertial>
          <inertia>
            <ixx>0.032</ixx>
            <ixy>0</ixy>
            <ixz>0</ixz>
            <iyy>0.032</iyy>
            <iyz>0</iyz>
            <izz>0.00012</izz>
          </inertia>
          <mass>0.6</mass>
        </inertial>
        <visual name="visual">
          <geometry>
            <box>
              <size>0.25 0.1 0.05</size>
            </box>
          </geometry>
          <material>
            <ambient>0.2 0.8 0.2 1</ambient>
            <diffuse>0.8 0 0 1</diffuse>
          </material>
        </visual>
        <collision name="collision">
          <geometry>
            <box>
              <size>0.25 0.1 0.05</size>
            </box>
          </geometry>
        </collision>
      </link>

      <joint name="world_fixed" type="fixed">
        <parent>world</parent>
        <child>base_link</child>
      </joint>

      <joint name="j1" type="revolute">
        <pose>0 0 -0.5 0 0 0</pose>
        <parent>base_link</parent>
        <child>rotor</child>
        <axis>
          <xyz>0 0 1</xyz>
        </axis>
      </joint>
      <!-- Velocity mode -->
      <plugin
        filename="gz-sim-joint-controller-system"
        name="gz::sim::systems::JointController">
        <joint_name>j1</joint_name>
        <initial_velocity>5.0</initial_velocity>
      </plugin>
    </model>

    <model name="joint_controller_demo_2">
      <pose>0 0.5 0 0 -1.57 0</pose>
      <link name="base_link">
        <pose>0.0 0.0 0.0 0 0 0</pose>
        <inertial>
          <inertia>
            <ixx>2.501</ixx>
            <ixy>0</ixy>
            <ixz>0</ixz>
            <iyy>2.501</iyy>
            <iyz>0</iyz>
            <izz>5</izz>
          </inertia>
          <mass>120.0</mass>
        </inertial>
        <visual name="base_visual">
          <pose>0.0 0.0 0.0 0 0 0</pose>
          <geometry>
            <box>
              <size>0.5 0.5 0.01</size>
            </box>
          </geometry>
        </visual>
        <collision name="base_collision">
          <pose>0.0 0.0 0.0 0 0 0</pose>
          <geometry>
            <box>
              <size>0.5 0.5 0.01</size>
            </box>
          </geometry>
        </collision>
      </link>
      <link name="rotor2">
        <pose>0.0 0.0 0.1 0 0 0</pose>
        <inertial>
          <inertia>
            <ixx>0.032</ixx>
            <ixy>0</ixy>
            <ixz>0</ixz>
            <iyy>0.032</iyy>
            <iyz>0</iyz>
            <izz>0.00012</izz>
          </inertia>
          <mass>0.6</mass>
        </inertial>
        <visual name="visual">
          <geometry>
            <box>
              <size>0.25 0.1 0.05</size>
            </box>
          </geometry>
          <material>
            <ambient>0.2 0.8 0.2 1</ambient>
            <diffuse>0.8 0 0 1</diffuse>
          </material>
        </visual>
        <collision name="collision">
          <geometry>
            <box>
              <size>0.25 0.1 0.05</size>
            </box>
          </geometry>
        </collision>
      </link>

      <joint name="world_fixed" type="fixed">
        <parent>world</parent>
        <child>base_link</child>
      </joint>

      <joint name="j1" type="revolute">
        <pose>0 0 -0.5 0 0 0</pose>
        <parent>base_link</parent>
        <child>rotor2</child>
        <axis>
          <xyz>0 0 1</xyz>
        </axis>
      </joint>

      <!-- Force mode -->
      <plugin
        filename="gz-sim-joint-controller-system"
        name="gz::sim::systems::JointController">
        <joint_name>j1</joint_name>
        <use_force_commands>true</use_force_commands>
        <p_gain>0.2</p_gain>
        <i_gain>0.01</i_gain>
      </plugin>
    </model>
  </world>
</sdf>
