<?xml version="1.0" ?>
<!--
  Gazebo sensor demo for sensors that do not require rendering.

  Listen to sensor readings:

    Altimeter: gz topic -e -t /altimeter
    Imu: gz topic -e -t /imu
    Magnetometer: gz topic -e -t /magnetometer
    Air pressure: gz topic -e -t /air_pressure
-->
<sdf version="1.6">
  <world name="sensors">
    <physics name="1ms" type="ignored">
      <max_step_size>0.001</max_step_size>
      <real_time_factor>1.0</real_time_factor>
    </physics>
    <plugin
      filename="gz-sim-physics-system"
      name="gz::sim::systems::Physics">
    </plugin>
    <plugin
      filename="gz-sim-air-pressure-system"
      name="gz::sim::systems::AirPressure">
    </plugin>
    <plugin
      filename="gz-sim-altimeter-system"
      name="gz::sim::systems::Altimeter">
    </plugin>
    <plugin
      filename="gz-sim-imu-system"
      name="gz::sim::systems::Imu">
    </plugin>
    <plugin
      filename="gz-sim-magnetometer-system"
      name="gz::sim::systems::Magnetometer">
    </plugin>
    <plugin
      filename="gz-sim-forcetorque-system"
      name="gz::sim::systems::ForceTorque">
      <gz::system_priority>10</gz::system_priority>
    </plugin>
    <plugin
      filename="gz-sim-user-commands-system"
      name="gz::sim::systems::UserCommands">
    </plugin>
    <plugin
      filename="gz-sim-scene-broadcaster-system"
      name="gz::sim::systems::SceneBroadcaster">
    </plugin>

    <light type="directional" name="sun">
      <cast_shadows>true</cast_shadows>
      <pose>0 0 10 0 0 0</pose>
      <diffuse>0.8 0.8 0.8 1</diffuse>
      <specular>0.2 0.2 0.2 1</specular>
      <attenuation>
        <range>1000</range>
        <constant>0.9</constant>
        <linear>0.01</linear>
        <quadratic>0.001</quadratic>
      </attenuation>
      <direction>-0.5 0.1 -0.9</direction>
    </light>

    <model name="ground_plane">
      <static>true</static>
      <link name="link">
        <collision name="collision">
          <geometry>
            <plane>
              <normal>0 0 1</normal>
              <size>100 100</size>
            </plane>
          </geometry>
        </collision>
        <visual name="visual">
          <geometry>
            <plane>
              <normal>0 0 1</normal>
              <size>100 100</size>
            </plane>
          </geometry>
          <material>
            <ambient>0.8 0.8 0.8 1</ambient>
            <diffuse>0.8 0.8 0.8 1</diffuse>
            <specular>0.8 0.8 0.8 1</specular>
          </material>
        </visual>
      </link>
    </model>

    <model name="sensors_box">
      <pose>4 0 3.0 0 0.0 3.14</pose>
      <link name="link">
        <pose>0.05 0.05 0.05 0 0 0</pose>
        <inertial>
          <mass>0.1</mass>
          <inertia>
            <ixx>0.000166667</ixx>
            <iyy>0.000166667</iyy>
            <izz>0.000166667</izz>
          </inertia>
        </inertial>
        <collision name="collision">
          <geometry>
            <box>
              <size>0.1 0.1 0.1</size>
            </box>
          </geometry>
        </collision>
        <visual name="visual">
          <geometry>
            <box>
              <size>0.1 0.1 0.1</size>
            </box>
          </geometry>
        </visual>
        <sensor name="altimeter" type="altimeter">
          <always_on>1</always_on>
          <update_rate>30</update_rate>
          <visualize>true</visualize>
          <topic>altimeter</topic>
          <enable_metrics>true</enable_metrics>
          <altimeter>
            <vertical_position>
              <noise type="gaussian">
                <mean>0.1</mean>
                <stddev>0.2</stddev>
              </noise>
            </vertical_position>
            <vertical_velocity>
              <noise type="gaussian">
                <mean>0.2</mean>
                <stddev>0.1</stddev>
              </noise>
            </vertical_velocity>
          </altimeter>
        </sensor>
        <sensor name="air_pressure" type="air_pressure">
          <always_on>1</always_on>
          <update_rate>30</update_rate>
          <visualize>true</visualize>
          <topic>air_pressure</topic>
          <enable_metrics>true</enable_metrics>
          <air_pressure>
            <reference_altitude>123</reference_altitude>
            <pressure>
              <noise type="gaussian">
                <mean>0.2</mean>
                <stddev>0.1</stddev>
              </noise>
            </pressure>
          </air_pressure>
        </sensor>
        <sensor name="air_speed" type="air_speed">
          <always_on>1</always_on>
          <update_rate>30</update_rate>
          <visualize>true</visualize>
          <topic>air_pressure</topic>
          <enable_metrics>true</enable_metrics>
          <air_speed>
            <pressure>
              <noise type="gaussian">
                <mean>0.2</mean>
                <stddev>0.1</stddev>
              </noise>
            </pressure>
          </air_speed>
        </sensor>
        <sensor name="imu" type="imu">
          <always_on>1</always_on>
          <update_rate>100</update_rate>
          <visualize>true</visualize>
          <topic>imu</topic>
          <enable_metrics>true</enable_metrics>
        </sensor>
        <sensor name="magnetometer" type="magnetometer">
          <always_on>1</always_on>
          <update_rate>100</update_rate>
          <visualize>true</visualize>
          <topic>magnetometer</topic>
          <enable_metrics>true</enable_metrics>
          <magnetometer>
            <x>
              <noise type="gaussian">
                <mean>0.0</mean>
                <stddev>0.1</stddev>
              </noise>
            </x>
            <y>
              <noise type="gaussian">
                <mean>0.0</mean>
                <stddev>0.1</stddev>
              </noise>
            </y>
            <z>
              <noise type="gaussian">
                <mean>0.0</mean>
                <stddev>0.1</stddev>
              </noise>
            </z>
          </magnetometer>
        </sensor>
      </link>
    </model>

    <model name="force_torque_demo">
      <link name="base_plate">
        <static>true</static>
      </link>

      <link name="link_1">
        <pose> 0 0 2.0 0 0 0</pose>
        <inertial>
          <inertia>
            <ixx>0.100000</ixx>
            <ixy>0.000000</ixy>
            <ixz>0.000000</ixz>
            <iyy>0.100000</iyy>
            <iyz>0.000000</iyz>
            <izz>0.100000</izz>
          </inertia>
          <mass>10.000000</mass>
        </inertial>
        <visual name="visual_sphere">
          <geometry>
            <sphere>
              <radius>0.100000</radius>
            </sphere>
          </geometry>
        </visual>
        <visual name="visual_cylinder">
          <pose>0 0 -0.75 0 0 0</pose>
          <geometry>
            <cylinder>
              <radius>0.0100000</radius>
              <length>1.5</length>
            </cylinder>
          </geometry>
        </visual>
        <collision name="collision_sphere">
          <geometry>
            <sphere>
              <radius>0.100000</radius>
            </sphere>
          </geometry>
        </collision>
      </link>
      <joint name="joint_00" type="fixed">
        <parent>world</parent>
        <child>base_plate</child>
      </joint>
      <joint name="joint_01" type="revolute">
        <parent>base_plate</parent>
        <child>link_1</child>
        <pose>0 0 -1.5 0 0 0</pose>
        <axis>
          <limit>
            <lower>-1.57079</lower>
            <upper>1.57079</upper>
          </limit>
          <dynamics>
            <damping>0.000000</damping>
            <friction>0.000000</friction>
          </dynamics>
          <xyz>1.000000 0.000000 0.000000</xyz>
        </axis>
        <sensor name="force_torque" type="force_torque">
          <update_rate>10</update_rate>
        </sensor>
      </joint>
    </model>
  </world>
</sdf>
